Traceback (most recent call last):
  File "/home/tjhunter/.cache/pypoetry/virtualenvs/climate-tutorials-Yg9kLiuM-py3.10/lib/python3.10/site-packages/jupyter_cache/executors/utils.py", line 58, in single_nb_execution
    executenb(
  File "/home/tjhunter/.cache/pypoetry/virtualenvs/climate-tutorials-Yg9kLiuM-py3.10/lib/python3.10/site-packages/nbclient/client.py", line 1314, in execute
    return NotebookClient(nb=nb, resources=resources, km=km, **kwargs).execute()
  File "/home/tjhunter/.cache/pypoetry/virtualenvs/climate-tutorials-Yg9kLiuM-py3.10/lib/python3.10/site-packages/jupyter_core/utils/__init__.py", line 165, in wrapped
    return loop.run_until_complete(inner)
  File "/usr/lib/python3.10/asyncio/base_events.py", line 649, in run_until_complete
    return future.result()
  File "/home/tjhunter/.cache/pypoetry/virtualenvs/climate-tutorials-Yg9kLiuM-py3.10/lib/python3.10/site-packages/nbclient/client.py", line 709, in async_execute
    await self.async_execute_cell(
  File "/home/tjhunter/.cache/pypoetry/virtualenvs/climate-tutorials-Yg9kLiuM-py3.10/lib/python3.10/site-packages/nbclient/client.py", line 1062, in async_execute_cell
    await self._check_raise_for_error(cell, cell_index, exec_reply)
  File "/home/tjhunter/.cache/pypoetry/virtualenvs/climate-tutorials-Yg9kLiuM-py3.10/lib/python3.10/site-packages/nbclient/client.py", line 918, in _check_raise_for_error
    raise CellExecutionError.from_cell_and_msg(cell, exec_reply_content)
nbclient.exceptions.CellExecutionError: An error occurred while executing the following cell:
------------------
with basic_model:
    idata = pm.sample(chains=num_chains)
------------------


[0;31m---------------------------------------------------------------------------[0m
[0;31mNameError[0m                                 Traceback (most recent call last)
Cell [0;32mIn[18], line 2[0m
[1;32m      1[0m [38;5;28;01mwith[39;00m basic_model:
[0;32m----> 2[0m     idata [38;5;241m=[39m pm[38;5;241m.[39msample(chains[38;5;241m=[39m[43mnum_chains[49m)

[0;31mNameError[0m: name 'num_chains' is not defined

